<?xml version="1.0"?>
	<robot name="mybot">
		
		<material name="white">
        	<color rgba="1 1 1 1"/>
		</material>

		<material name="orange">
		    <color rgba="1 0.3 0.1 1"/>
		</material>

		<material name="blue">
		    <color rgba="0.2 0.2 1 1"/>
		</material>

		<material name="black">
		    <color rgba="0 0 0 1"/>
		</material>

		<material name="red">
		    <color rgba="1 0 0 1"/>
		</material>
		
		<link name="base_link">				
		</link>

		<!--Chassis-->
		<joint name="chassis_joint" type="fixed">
		    <parent link="base_link"/>
		    <child link="chassis"/>
		    <origin xyz="0 0 0.033"/>
		</joint>

		<link name="chassis">
		    <visual>
		        <origin xyz="0 0 0.075" rpy="0 0 0"/>
		        <geometry>
		            <cylinder radius="0.12" length="0.15"/>
		        </geometry>
		        <material name="orange"/>
		    </visual>
		</link>
		
		<!--lidar-->	
		<joint name="base_link_to_laser" type="fixed">
			<parent link="base_link"/>
			<child link="laser"/>
			<origin xyz="0.0 0.0 0.2" rpy="0.0 0.0 0.0"/>
			<axis xyz="0 0 0"/>
		</joint>
		
		<link name="laser">	
			<visual>
		        <geometry>
		            <cylinder radius="0.04" length="0.07"/>
		        </geometry>
		        <material name="red"/>
		    </visual>	
		</link>
			
		
		<!--Left wheel-->
		<joint name="left_wheel_joint" type="continuous">
		    <parent link="base_link"/>
		    <child link="left_wheel"/>
		    <origin xyz="0.03 0.132 0.033" rpy="-1.57079 0 0"/>
		    <axis xyz="0 0 1"/>
		</joint>

		<link name="left_wheel">
		    <visual>
		        <geometry>
		            <cylinder radius="0.033" length="0.025"/>
		        </geometry>
		        <material name="blue"/>
		    </visual>
		</link>
		
		<!--Right wheel-->
		<joint name="right_wheel_joint" type="continuous">
		    <parent link="base_link"/>
		    <child link="right_wheel"/>
		    <origin xyz="0.03 -0.132 0.033" rpy="1.57079 0 0"/>
		    <axis xyz="0 0 -1"/>
		</joint>

		<link name="right_wheel">
		    <visual>
		        <geometry>
		            <cylinder radius="0.033" length="0.025"/>
		        </geometry>
		        <material name="blue"/>
		    </visual>
		</link>
		
		<!--Caster wheel-->
		<joint name="caster_wheel_joint" type="fixed">
		    <parent link="base_link"/>
		    <child link="caster_wheel"/>
		    <origin xyz="-0.08 0.0 0.033"/>
		</joint>

		<link name="caster_wheel">
		    <visual>
		        <geometry>
		            <sphere radius="0.033"/>
		        </geometry>
		        <material name="black"/>
		    </visual>
		</link>
		
	</robot>
